Traceback (most recent call last):
  File "C:\Users\Queuebee\AppData\Local\Programs\Python\Python36-32\lib\urllib\request.py", line 1318, in do_open
    encode_chunked=req.has_header('Transfer-encoding'))
  File "C:\Users\Queuebee\AppData\Local\Programs\Python\Python36-32\lib\http\client.py", line 1239, in request
    self._send_request(method, url, body, headers, encode_chunked)
  File "C:\Users\Queuebee\AppData\Local\Programs\Python\Python36-32\lib\http\client.py", line 1285, in _send_request
    self.endheaders(body, encode_chunked=encode_chunked)
  File "C:\Users\Queuebee\AppData\Local\Programs\Python\Python36-32\lib\http\client.py", line 1234, in endheaders
    self._send_output(message_body, encode_chunked=encode_chunked)
  File "C:\Users\Queuebee\AppData\Local\Programs\Python\Python36-32\lib\http\client.py", line 1026, in _send_output
    self.send(msg)
  File "C:\Users\Queuebee\AppData\Local\Programs\Python\Python36-32\lib\http\client.py", line 964, in send
    self.connect()
  File "C:\Users\Queuebee\AppData\Local\Programs\Python\Python36-32\lib\http\client.py", line 1392, in connect
    super().connect()
  File "C:\Users\Queuebee\AppData\Local\Programs\Python\Python36-32\lib\http\client.py", line 936, in connect
    (self.host,self.port), self.timeout, self.source_address)
  File "C:\Users\Queuebee\AppData\Local\Programs\Python\Python36-32\lib\socket.py", line 704, in create_connection
    for res in getaddrinfo(host, port, 0, SOCK_STREAM):
  File "C:\Users\Queuebee\AppData\Local\Programs\Python\Python36-32\lib\socket.py", line 745, in getaddrinfo
    for res in _socket.getaddrinfo(host, port, family, type, proto, flags):
socket.gaierror: [Errno 11001] getaddrinfo failed

During handling of the above exception, another exception occurred:

Traceback (most recent call last):
  File "D:\HAN\BLOK4\TUTOR\Course4Tutor\weektaak_1\main.py", line 275, in <module>
    main()
  File "D:\HAN\BLOK4\TUTOR\Course4Tutor\weektaak_1\main.py", line 151, in main
    doBlast(DEFAULT_BLAST_FILENAME, **kwargs)
  File "D:\HAN\BLOK4\TUTOR\Course4Tutor\weektaak_1\blastaseq.py", line 51, in doBlast
    result_handle = NCBIWWW.qblast(**kwargs)
  File "C:\Users\Queuebee\AppData\Local\Programs\Python\Python36-32\lib\site-packages\Bio\Blast\NCBIWWW.py", line 137, in qblast
    handle = _urlopen(request)
  File "C:\Users\Queuebee\AppData\Local\Programs\Python\Python36-32\lib\urllib\request.py", line 223, in urlopen
    return opener.open(url, data, timeout)
  File "C:\Users\Queuebee\AppData\Local\Programs\Python\Python36-32\lib\urllib\request.py", line 526, in open
    response = self._open(req, data)
  File "C:\Users\Queuebee\AppData\Local\Programs\Python\Python36-32\lib\urllib\request.py", line 544, in _open
    '_open', req)
  File "C:\Users\Queuebee\AppData\Local\Programs\Python\Python36-32\lib\urllib\request.py", line 504, in _call_chain
    result = func(*args)
  File "C:\Users\Queuebee\AppData\Local\Programs\Python\Python36-32\lib\urllib\request.py", line 1361, in https_open
    context=self._context, check_hostname=self._check_hostname)
  File "C:\Users\Queuebee\AppData\Local\Programs\Python\Python36-32\lib\urllib\request.py", line 1320, in do_open
    raise URLError(err)
urllib.error.URLError: <urlopen error [Errno 11001] getaddrinfo failed>